/home/EBookBot/server/backend/templates.py:6: UserWarning: async_to_sync was passed a non-async-marked callable
  START_COMMAND_HANDLER = async_to_sync(Template.messages.get)(id=2).gettext()
/home/EBookBot/server/backend/templates.py:7: UserWarning: async_to_sync was passed a non-async-marked callable
  SEARCH = async_to_sync(Template.messages.get)(id=7).gettext()
/home/EBookBot/server/backend/templates.py:8: UserWarning: async_to_sync was passed a non-async-marked callable
  SEARCHING = async_to_sync(Template.messages.get)(id=8).gettext()
/home/EBookBot/server/backend/templates.py:9: UserWarning: async_to_sync was passed a non-async-marked callable
  SEARCH_RESULT = async_to_sync(Template.messages.get)(id=9).gettext()
/home/EBookBot/server/backend/templates.py:10: UserWarning: async_to_sync was passed a non-async-marked callable
  BOOK_LIST_INFO = async_to_sync(Template.messages.get)(id=10).gettext()
/home/EBookBot/server/backend/templates.py:11: UserWarning: async_to_sync was passed a non-async-marked callable
  BOOK_DETAIL = async_to_sync(Template.messages.get)(id=12).gettext()
/home/EBookBot/server/backend/templates.py:12: UserWarning: async_to_sync was passed a non-async-marked callable
  MANDATORY_SUBSCRIPTION = async_to_sync(Template.messages.get)(id=16).gettext()
/home/EBookBot/server/backend/templates.py:13: UserWarning: async_to_sync was passed a non-async-marked callable
  NOT_SUBSCRIBED = async_to_sync(Template.messages.get)(id=18).gettext()
/home/EBookBot/server/backend/templates.py:14: UserWarning: async_to_sync was passed a non-async-marked callable
  SUBSCRIBED_SUCCESS = async_to_sync(Template.messages.get)(id=19).gettext()
/home/EBookBot/server/backend/templates.py:15: UserWarning: async_to_sync was passed a non-async-marked callable
  BOOK_DOWNLOADING = async_to_sync(Template.messages.get)(id=20).gettext()
/home/EBookBot/server/backend/templates.py:16: UserWarning: async_to_sync was passed a non-async-marked callable
  ABOUT = async_to_sync(Template.messages.get)(id=21).gettext()
/home/EBookBot/server/backend/templates.py:20: UserWarning: async_to_sync was passed a non-async-marked callable
  MENU = async_to_sync(Template.keys.get)(id=3).gettext()
/home/EBookBot/server/backend/templates.py:21: UserWarning: async_to_sync was passed a non-async-marked callable
  SEARCH = async_to_sync(Template.keys.get)(id=4).gettext()
/home/EBookBot/server/backend/templates.py:22: UserWarning: async_to_sync was passed a non-async-marked callable
  FAVORITES = async_to_sync(Template.keys.get)(id=5).gettext()
/home/EBookBot/server/backend/templates.py:23: UserWarning: async_to_sync was passed a non-async-marked callable
  ABOUT = async_to_sync(Template.keys.get)(id=6).gettext()
/home/EBookBot/server/backend/templates.py:24: UserWarning: async_to_sync was passed a non-async-marked callable
  BACK = async_to_sync(Template.keys.get)(id=13).gettext()
/home/EBookBot/server/backend/templates.py:25: UserWarning: async_to_sync was passed a non-async-marked callable
  BY_AUTHOR = async_to_sync(Template.keys.get)(id=14).gettext()
/home/EBookBot/server/backend/templates.py:26: UserWarning: async_to_sync was passed a non-async-marked callable
  TO_FAVORITES = async_to_sync(Template.keys.get)(id=15).gettext()
/home/EBookBot/server/backend/templates.py:27: UserWarning: async_to_sync was passed a non-async-marked callable
  SUBSCRIBED = async_to_sync(Template.keys.get)(id=17).gettext()
/home/EBookBot/server/backend/templates.py:28: UserWarning: async_to_sync was passed a non-async-marked callable
  ADD_TO_GROUP = async_to_sync(Template.keys.get)(id=22).gettext()
/home/EBookBot/server/backend/templates.py:32: UserWarning: async_to_sync was passed a non-async-marked callable
  NEXT_PAGE = async_to_sync(Template.smiles.get)(id=1).gettext()
/home/EBookBot/server/backend/templates.py:33: UserWarning: async_to_sync was passed a non-async-marked callable
  PREV_PAGE = async_to_sync(Template.smiles.get)(id=11).gettext()
INFO:aiogram:Bot: EBookBot [@cpebookbot]
WARNING:aiogram:Updates were skipped successfully.
INFO:aiogram.dispatcher.dispatcher:Start polling.
ERROR:asyncio:Task exception was never retrieved
future: <Task finished name='Task-506' coro=<Dispatcher._process_polling_updates() done, defined at /usr/local/lib/python3.10/site-packages/aiogram/dispatcher/dispatcher.py:407> exception=AttributeError("'NoneType' object has no attribute 'text'")>
Traceback (most recent call last):
  File "/usr/local/lib/python3.10/site-packages/aiogram/dispatcher/dispatcher.py", line 415, in _process_polling_updates
    for responses in itertools.chain.from_iterable(await self.process_updates(updates, fast)):
  File "/usr/local/lib/python3.10/site-packages/aiogram/dispatcher/dispatcher.py", line 235, in process_updates
    return await asyncio.gather(*tasks)
  File "/usr/local/lib/python3.10/site-packages/aiogram/dispatcher/handler.py", line 116, in notify
    response = await handler_obj.handler(*args, **partial_data)
  File "/usr/local/lib/python3.10/site-packages/aiogram/dispatcher/dispatcher.py", line 256, in process_update
    return await self.message_handlers.notify(update.message)
  File "/usr/local/lib/python3.10/site-packages/aiogram/dispatcher/handler.py", line 116, in notify
    response = await handler_obj.handler(*args, **partial_data)
  File "/home/EBookBot/client/bot.py", line 55, in message_handler
    await state_handlers[user.bot_state](bot, message)
  File "/home/EBookBot/client/handlers.py", line 58, in search_text_message_handler
    await search_result_callback_query_handler(bot, message)
  File "/home/EBookBot/client/handlers.py", line 82, in search_result_callback_query_handler
    book = await utils.get_book(book.id)
  File "/home/EBookBot/client/utils.py", line 18, in get_book
    return await flibusta.get_book(book_id)
  File "/home/EBookBot/parser/flibusta.py", line 84, in get_book
    book = parse_book(html)
  File "/home/EBookBot/parser/flibusta.py", line 45, in parse_book
    text = soup.find(string=re.compile('издание')).text.strip()
AttributeError: 'NoneType' object has no attribute 'text'
ERROR:asyncio:Task exception was never retrieved
future: <Task finished name='Task-528' coro=<Dispatcher._process_polling_updates() done, defined at /usr/local/lib/python3.10/site-packages/aiogram/dispatcher/dispatcher.py:407> exception=AttributeError("'NoneType' object has no attribute 'text'")>
Traceback (most recent call last):
  File "/usr/local/lib/python3.10/site-packages/aiogram/dispatcher/dispatcher.py", line 415, in _process_polling_updates
    for responses in itertools.chain.from_iterable(await self.process_updates(updates, fast)):
  File "/usr/local/lib/python3.10/site-packages/aiogram/dispatcher/dispatcher.py", line 235, in process_updates
    return await asyncio.gather(*tasks)
  File "/usr/local/lib/python3.10/site-packages/aiogram/dispatcher/handler.py", line 116, in notify
    response = await handler_obj.handler(*args, **partial_data)
  File "/usr/local/lib/python3.10/site-packages/aiogram/dispatcher/dispatcher.py", line 256, in process_update
    return await self.message_handlers.notify(update.message)
  File "/usr/local/lib/python3.10/site-packages/aiogram/dispatcher/handler.py", line 116, in notify
    response = await handler_obj.handler(*args, **partial_data)
  File "/home/EBookBot/client/bot.py", line 55, in message_handler
    await state_handlers[user.bot_state](bot, message)
  File "/home/EBookBot/client/handlers.py", line 58, in search_text_message_handler
    await search_result_callback_query_handler(bot, message)
  File "/home/EBookBot/client/handlers.py", line 82, in search_result_callback_query_handler
    book = await utils.get_book(book.id)
  File "/home/EBookBot/client/utils.py", line 18, in get_book
    return await flibusta.get_book(book_id)
  File "/home/EBookBot/parser/flibusta.py", line 84, in get_book
    book = parse_book(html)
  File "/home/EBookBot/parser/flibusta.py", line 45, in parse_book
    text = soup.find(string=re.compile('издание')).text.strip()
AttributeError: 'NoneType' object has no attribute 'text'
/home/EBookBot/server/backend/templates.py:6: UserWarning: async_to_sync was passed a non-async-marked callable
  START_COMMAND_HANDLER = async_to_sync(Template.messages.get)(id=2).gettext()
/home/EBookBot/server/backend/templates.py:7: UserWarning: async_to_sync was passed a non-async-marked callable
  SEARCH = async_to_sync(Template.messages.get)(id=7).gettext()
/home/EBookBot/server/backend/templates.py:8: UserWarning: async_to_sync was passed a non-async-marked callable
  SEARCHING = async_to_sync(Template.messages.get)(id=8).gettext()
/home/EBookBot/server/backend/templates.py:9: UserWarning: async_to_sync was passed a non-async-marked callable
  SEARCH_RESULT = async_to_sync(Template.messages.get)(id=9).gettext()
/home/EBookBot/server/backend/templates.py:10: UserWarning: async_to_sync was passed a non-async-marked callable
  BOOK_LIST_INFO = async_to_sync(Template.messages.get)(id=10).gettext()
/home/EBookBot/server/backend/templates.py:11: UserWarning: async_to_sync was passed a non-async-marked callable
  BOOK_DETAIL = async_to_sync(Template.messages.get)(id=12).gettext()
/home/EBookBot/server/backend/templates.py:12: UserWarning: async_to_sync was passed a non-async-marked callable
  MANDATORY_SUBSCRIPTION = async_to_sync(Template.messages.get)(id=16).gettext()
/home/EBookBot/server/backend/templates.py:13: UserWarning: async_to_sync was passed a non-async-marked callable
  NOT_SUBSCRIBED = async_to_sync(Template.messages.get)(id=18).gettext()
/home/EBookBot/server/backend/templates.py:14: UserWarning: async_to_sync was passed a non-async-marked callable
  SUBSCRIBED_SUCCESS = async_to_sync(Template.messages.get)(id=19).gettext()
/home/EBookBot/server/backend/templates.py:15: UserWarning: async_to_sync was passed a non-async-marked callable
  BOOK_DOWNLOADING = async_to_sync(Template.messages.get)(id=20).gettext()
/home/EBookBot/server/backend/templates.py:16: UserWarning: async_to_sync was passed a non-async-marked callable
  ABOUT = async_to_sync(Template.messages.get)(id=21).gettext()
/home/EBookBot/server/backend/templates.py:20: UserWarning: async_to_sync was passed a non-async-marked callable
  MENU = async_to_sync(Template.keys.get)(id=3).gettext()
/home/EBookBot/server/backend/templates.py:21: UserWarning: async_to_sync was passed a non-async-marked callable
  SEARCH = async_to_sync(Template.keys.get)(id=4).gettext()
/home/EBookBot/server/backend/templates.py:22: UserWarning: async_to_sync was passed a non-async-marked callable
  FAVORITES = async_to_sync(Template.keys.get)(id=5).gettext()
/home/EBookBot/server/backend/templates.py:23: UserWarning: async_to_sync was passed a non-async-marked callable
  ABOUT = async_to_sync(Template.keys.get)(id=6).gettext()
/home/EBookBot/server/backend/templates.py:24: UserWarning: async_to_sync was passed a non-async-marked callable
  BACK = async_to_sync(Template.keys.get)(id=13).gettext()
/home/EBookBot/server/backend/templates.py:25: UserWarning: async_to_sync was passed a non-async-marked callable
  BY_AUTHOR = async_to_sync(Template.keys.get)(id=14).gettext()
/home/EBookBot/server/backend/templates.py:26: UserWarning: async_to_sync was passed a non-async-marked callable
  TO_FAVORITES = async_to_sync(Template.keys.get)(id=15).gettext()
/home/EBookBot/server/backend/templates.py:27: UserWarning: async_to_sync was passed a non-async-marked callable
  SUBSCRIBED = async_to_sync(Template.keys.get)(id=17).gettext()
/home/EBookBot/server/backend/templates.py:28: UserWarning: async_to_sync was passed a non-async-marked callable
  ADD_TO_GROUP = async_to_sync(Template.keys.get)(id=22).gettext()
/home/EBookBot/server/backend/templates.py:32: UserWarning: async_to_sync was passed a non-async-marked callable
  NEXT_PAGE = async_to_sync(Template.smiles.get)(id=1).gettext()
/home/EBookBot/server/backend/templates.py:33: UserWarning: async_to_sync was passed a non-async-marked callable
  PREV_PAGE = async_to_sync(Template.smiles.get)(id=11).gettext()
INFO:aiogram:Bot: EBookBot [@cpebookbot]
WARNING:aiogram:Updates were skipped successfully.
INFO:aiogram.dispatcher.dispatcher:Start polling.
ERROR:asyncio:Task exception was never retrieved
future: <Task finished name='Task-8448' coro=<Dispatcher._process_polling_updates() done, defined at /usr/local/lib/python3.10/site-packages/aiogram/dispatcher/dispatcher.py:407> exception=ButtonDataInvalid('Button_data_invalid')>
Traceback (most recent call last):
  File "/usr/local/lib/python3.10/site-packages/aiogram/dispatcher/dispatcher.py", line 415, in _process_polling_updates
    for responses in itertools.chain.from_iterable(await self.process_updates(updates, fast)):
  File "/usr/local/lib/python3.10/site-packages/aiogram/dispatcher/dispatcher.py", line 235, in process_updates
    return await asyncio.gather(*tasks)
  File "/usr/local/lib/python3.10/site-packages/aiogram/dispatcher/handler.py", line 116, in notify
    response = await handler_obj.handler(*args, **partial_data)
  File "/usr/local/lib/python3.10/site-packages/aiogram/dispatcher/dispatcher.py", line 256, in process_update
    return await self.message_handlers.notify(update.message)
  File "/usr/local/lib/python3.10/site-packages/aiogram/dispatcher/handler.py", line 116, in notify
    response = await handler_obj.handler(*args, **partial_data)
  File "/home/EBookBot/client/bot.py", line 55, in message_handler
    await state_handlers[user.bot_state](bot, message)
  File "/home/EBookBot/client/handlers.py", line 58, in search_text_message_handler
    await search_result_callback_query_handler(bot, message)
  File "/home/EBookBot/client/handlers.py", line 110, in search_result_callback_query_handler
    await bot.send_message(chat_id, text,
  File "/usr/local/lib/python3.10/site-packages/aiogram/bot/bot.py", line 334, in send_message
    result = await self.request(api.Methods.SEND_MESSAGE, payload)
  File "/usr/local/lib/python3.10/site-packages/aiogram/bot/base.py", line 231, in request
    return await api.make_request(await self.get_session(), self.server, self.__token, method, data, files,
  File "/usr/local/lib/python3.10/site-packages/aiogram/bot/api.py", line 140, in make_request
    return check_result(method, response.content_type, response.status, await response.text())
  File "/usr/local/lib/python3.10/site-packages/aiogram/bot/api.py", line 115, in check_result
    exceptions.BadRequest.detect(description)
  File "/usr/local/lib/python3.10/site-packages/aiogram/utils/exceptions.py", line 140, in detect
    raise err(cls.text or description)
aiogram.utils.exceptions.ButtonDataInvalid: Button_data_invalid
ERROR:asyncio:Task exception was never retrieved
future: <Task finished name='Task-8489' coro=<Dispatcher._process_polling_updates() done, defined at /usr/local/lib/python3.10/site-packages/aiogram/dispatcher/dispatcher.py:407> exception=IndexError('list index out of range')>
Traceback (most recent call last):
  File "/usr/local/lib/python3.10/site-packages/aiogram/dispatcher/dispatcher.py", line 415, in _process_polling_updates
    for responses in itertools.chain.from_iterable(await self.process_updates(updates, fast)):
  File "/usr/local/lib/python3.10/site-packages/aiogram/dispatcher/dispatcher.py", line 235, in process_updates
    return await asyncio.gather(*tasks)
  File "/usr/local/lib/python3.10/site-packages/aiogram/dispatcher/handler.py", line 116, in notify
    response = await handler_obj.handler(*args, **partial_data)
  File "/usr/local/lib/python3.10/site-packages/aiogram/dispatcher/dispatcher.py", line 283, in process_update
    return await self.callback_query_handlers.notify(update.callback_query)
  File "/usr/local/lib/python3.10/site-packages/aiogram/dispatcher/handler.py", line 116, in notify
    response = await handler_obj.handler(*args, **partial_data)
  File "/home/EBookBot/client/bot.py", line 71, in callback_query_handler
    await handler(bot, call)
  File "/home/EBookBot/client/handlers.py", line 82, in search_result_callback_query_handler
    book = await utils.get_book(book.id)
  File "/home/EBookBot/client/utils.py", line 18, in get_book
    return await flibusta.get_book(book_id)
  File "/home/EBookBot/parser/flibusta.py", line 86, in get_book
    book = parse_book(html)
  File "/home/EBookBot/parser/flibusta.py", line 47, in parse_book
    book.year_public = re.findall(r'\d{4}', text)[0]
IndexError: list index out of range
ERROR:asyncio:Task exception was never retrieved
future: <Task finished name='Task-8502' coro=<Dispatcher._process_polling_updates() done, defined at /usr/local/lib/python3.10/site-packages/aiogram/dispatcher/dispatcher.py:407> exception=IndexError('list index out of range')>
Traceback (most recent call last):
  File "/usr/local/lib/python3.10/site-packages/aiogram/dispatcher/dispatcher.py", line 415, in _process_polling_updates
    for responses in itertools.chain.from_iterable(await self.process_updates(updates, fast)):
  File "/usr/local/lib/python3.10/site-packages/aiogram/dispatcher/dispatcher.py", line 235, in process_updates
    return await asyncio.gather(*tasks)
  File "/usr/local/lib/python3.10/site-packages/aiogram/dispatcher/handler.py", line 116, in notify
    response = await handler_obj.handler(*args, **partial_data)
  File "/usr/local/lib/python3.10/site-packages/aiogram/dispatcher/dispatcher.py", line 283, in process_update
    return await self.callback_query_handlers.notify(update.callback_query)
  File "/usr/local/lib/python3.10/site-packages/aiogram/dispatcher/handler.py", line 116, in notify
    response = await handler_obj.handler(*args, **partial_data)
  File "/home/EBookBot/client/bot.py", line 71, in callback_query_handler
    await handler(bot, call)
  File "/home/EBookBot/client/handlers.py", line 82, in search_result_callback_query_handler
    book = await utils.get_book(book.id)
  File "/home/EBookBot/client/utils.py", line 18, in get_book
    return await flibusta.get_book(book_id)
  File "/home/EBookBot/parser/flibusta.py", line 86, in get_book
    book = parse_book(html)
  File "/home/EBookBot/parser/flibusta.py", line 47, in parse_book
    book.year_public = re.findall(r'\d{4}', text)[0]
IndexError: list index out of range
ERROR:asyncio:Task exception was never retrieved
future: <Task finished name='Task-8515' coro=<Dispatcher._process_polling_updates() done, defined at /usr/local/lib/python3.10/site-packages/aiogram/dispatcher/dispatcher.py:407> exception=IndexError('list index out of range')>
Traceback (most recent call last):
  File "/usr/local/lib/python3.10/site-packages/aiogram/dispatcher/dispatcher.py", line 415, in _process_polling_updates
    for responses in itertools.chain.from_iterable(await self.process_updates(updates, fast)):
  File "/usr/local/lib/python3.10/site-packages/aiogram/dispatcher/dispatcher.py", line 235, in process_updates
    return await asyncio.gather(*tasks)
  File "/usr/local/lib/python3.10/site-packages/aiogram/dispatcher/handler.py", line 116, in notify
    response = await handler_obj.handler(*args, **partial_data)
  File "/usr/local/lib/python3.10/site-packages/aiogram/dispatcher/dispatcher.py", line 283, in process_update
    return await self.callback_query_handlers.notify(update.callback_query)
  File "/usr/local/lib/python3.10/site-packages/aiogram/dispatcher/handler.py", line 116, in notify
    response = await handler_obj.handler(*args, **partial_data)
  File "/home/EBookBot/client/bot.py", line 71, in callback_query_handler
    await handler(bot, call)
  File "/home/EBookBot/client/handlers.py", line 82, in search_result_callback_query_handler
    book = await utils.get_book(book.id)
  File "/home/EBookBot/client/utils.py", line 18, in get_book
    return await flibusta.get_book(book_id)
  File "/home/EBookBot/parser/flibusta.py", line 86, in get_book
    book = parse_book(html)
  File "/home/EBookBot/parser/flibusta.py", line 47, in parse_book
    book.year_public = re.findall(r'\d{4}', text)[0]
IndexError: list index out of range
ERROR:asyncio:Task exception was never retrieved
future: <Task finished name='Task-8528' coro=<Dispatcher._process_polling_updates() done, defined at /usr/local/lib/python3.10/site-packages/aiogram/dispatcher/dispatcher.py:407> exception=IndexError('list index out of range')>
Traceback (most recent call last):
  File "/usr/local/lib/python3.10/site-packages/aiogram/dispatcher/dispatcher.py", line 415, in _process_polling_updates
    for responses in itertools.chain.from_iterable(await self.process_updates(updates, fast)):
  File "/usr/local/lib/python3.10/site-packages/aiogram/dispatcher/dispatcher.py", line 235, in process_updates
    return await asyncio.gather(*tasks)
  File "/usr/local/lib/python3.10/site-packages/aiogram/dispatcher/handler.py", line 116, in notify
    response = await handler_obj.handler(*args, **partial_data)
  File "/usr/local/lib/python3.10/site-packages/aiogram/dispatcher/dispatcher.py", line 283, in process_update
    return await self.callback_query_handlers.notify(update.callback_query)
  File "/usr/local/lib/python3.10/site-packages/aiogram/dispatcher/handler.py", line 116, in notify
    response = await handler_obj.handler(*args, **partial_data)
  File "/home/EBookBot/client/bot.py", line 71, in callback_query_handler
    await handler(bot, call)
  File "/home/EBookBot/client/handlers.py", line 82, in search_result_callback_query_handler
    book = await utils.get_book(book.id)
  File "/home/EBookBot/client/utils.py", line 18, in get_book
    return await flibusta.get_book(book_id)
  File "/home/EBookBot/parser/flibusta.py", line 86, in get_book
    book = parse_book(html)
  File "/home/EBookBot/parser/flibusta.py", line 47, in parse_book
    book.year_public = re.findall(r'\d{4}', text)[0]
IndexError: list index out of range
ERROR:asyncio:Task exception was never retrieved
future: <Task finished name='Task-8550' coro=<Dispatcher._process_polling_updates() done, defined at /usr/local/lib/python3.10/site-packages/aiogram/dispatcher/dispatcher.py:407> exception=ButtonDataInvalid('Button_data_invalid')>
Traceback (most recent call last):
  File "/usr/local/lib/python3.10/site-packages/aiogram/dispatcher/dispatcher.py", line 415, in _process_polling_updates
    for responses in itertools.chain.from_iterable(await self.process_updates(updates, fast)):
  File "/usr/local/lib/python3.10/site-packages/aiogram/dispatcher/dispatcher.py", line 235, in process_updates
    return await asyncio.gather(*tasks)
  File "/usr/local/lib/python3.10/site-packages/aiogram/dispatcher/handler.py", line 116, in notify
    response = await handler_obj.handler(*args, **partial_data)
  File "/usr/local/lib/python3.10/site-packages/aiogram/dispatcher/dispatcher.py", line 256, in process_update
    return await self.message_handlers.notify(update.message)
  File "/usr/local/lib/python3.10/site-packages/aiogram/dispatcher/handler.py", line 116, in notify
    response = await handler_obj.handler(*args, **partial_data)
  File "/home/EBookBot/client/bot.py", line 55, in message_handler
    await state_handlers[user.bot_state](bot, message)
  File "/home/EBookBot/client/handlers.py", line 58, in search_text_message_handler
    await search_result_callback_query_handler(bot, message)
  File "/home/EBookBot/client/handlers.py", line 110, in search_result_callback_query_handler
    await bot.send_message(chat_id, text,
  File "/usr/local/lib/python3.10/site-packages/aiogram/bot/bot.py", line 334, in send_message
    result = await self.request(api.Methods.SEND_MESSAGE, payload)
  File "/usr/local/lib/python3.10/site-packages/aiogram/bot/base.py", line 231, in request
    return await api.make_request(await self.get_session(), self.server, self.__token, method, data, files,
  File "/usr/local/lib/python3.10/site-packages/aiogram/bot/api.py", line 140, in make_request
    return check_result(method, response.content_type, response.status, await response.text())
  File "/usr/local/lib/python3.10/site-packages/aiogram/bot/api.py", line 115, in check_result
    exceptions.BadRequest.detect(description)
  File "/usr/local/lib/python3.10/site-packages/aiogram/utils/exceptions.py", line 140, in detect
    raise err(cls.text or description)
aiogram.utils.exceptions.ButtonDataInvalid: Button_data_invalid
ERROR:asyncio:Task exception was never retrieved
future: <Task finished name='Task-8588' coro=<Dispatcher._process_polling_updates() done, defined at /usr/local/lib/python3.10/site-packages/aiogram/dispatcher/dispatcher.py:407> exception=IndexError('list index out of range')>
Traceback (most recent call last):
  File "/usr/local/lib/python3.10/site-packages/aiogram/dispatcher/dispatcher.py", line 415, in _process_polling_updates
    for responses in itertools.chain.from_iterable(await self.process_updates(updates, fast)):
  File "/usr/local/lib/python3.10/site-packages/aiogram/dispatcher/dispatcher.py", line 235, in process_updates
    return await asyncio.gather(*tasks)
  File "/usr/local/lib/python3.10/site-packages/aiogram/dispatcher/handler.py", line 116, in notify
    response = await handler_obj.handler(*args, **partial_data)
  File "/usr/local/lib/python3.10/site-packages/aiogram/dispatcher/dispatcher.py", line 283, in process_update
    return await self.callback_query_handlers.notify(update.callback_query)
  File "/usr/local/lib/python3.10/site-packages/aiogram/dispatcher/handler.py", line 116, in notify
    response = await handler_obj.handler(*args, **partial_data)
  File "/home/EBookBot/client/bot.py", line 71, in callback_query_handler
    await handler(bot, call)
  File "/home/EBookBot/client/handlers.py", line 82, in search_result_callback_query_handler
    book = await utils.get_book(book.id)
  File "/home/EBookBot/client/utils.py", line 18, in get_book
    return await flibusta.get_book(book_id)
  File "/home/EBookBot/parser/flibusta.py", line 86, in get_book
    book = parse_book(html)
  File "/home/EBookBot/parser/flibusta.py", line 47, in parse_book
    book.year_public = re.findall(r'\d{4}', text)[0]
IndexError: list index out of range
ERROR:aiogram.dispatcher.dispatcher:Cause exception while getting updates.
Traceback (most recent call last):
  File "/usr/local/lib/python3.10/site-packages/aiogram/dispatcher/dispatcher.py", line 381, in start_polling
    updates = await self.bot.get_updates(
  File "/usr/local/lib/python3.10/site-packages/aiogram/bot/bot.py", line 110, in get_updates
    result = await self.request(api.Methods.GET_UPDATES, payload)
  File "/usr/local/lib/python3.10/site-packages/aiogram/bot/base.py", line 231, in request
    return await api.make_request(await self.get_session(), self.server, self.__token, method, data, files,
  File "/usr/local/lib/python3.10/site-packages/aiogram/bot/api.py", line 140, in make_request
    return check_result(method, response.content_type, response.status, await response.text())
  File "/usr/local/lib/python3.10/site-packages/aiogram/bot/api.py", line 128, in check_result
    raise exceptions.TelegramAPIError(description)
aiogram.utils.exceptions.TelegramAPIError: Gateway Timeout
ERROR:aiogram.dispatcher.dispatcher:Cause exception while getting updates.
Traceback (most recent call last):
  File "/usr/local/lib/python3.10/site-packages/aiogram/dispatcher/dispatcher.py", line 381, in start_polling
    updates = await self.bot.get_updates(
  File "/usr/local/lib/python3.10/site-packages/aiogram/bot/bot.py", line 110, in get_updates
    result = await self.request(api.Methods.GET_UPDATES, payload)
  File "/usr/local/lib/python3.10/site-packages/aiogram/bot/base.py", line 231, in request
    return await api.make_request(await self.get_session(), self.server, self.__token, method, data, files,
  File "/usr/local/lib/python3.10/site-packages/aiogram/bot/api.py", line 139, in make_request
    async with session.post(url, data=req, **kwargs) as response:
  File "/usr/local/lib/python3.10/site-packages/aiohttp/client.py", line 1138, in __aenter__
    self._resp = await self._coro
  File "/usr/local/lib/python3.10/site-packages/aiohttp/client.py", line 559, in _request
    await resp.start(conn)
  File "/usr/local/lib/python3.10/site-packages/aiohttp/client_reqrep.py", line 893, in start
    with self._timer:
  File "/usr/local/lib/python3.10/site-packages/aiohttp/helpers.py", line 721, in __exit__
    raise asyncio.TimeoutError from None
asyncio.exceptions.TimeoutError
ERROR:aiogram.dispatcher.dispatcher:Cause exception while getting updates.
Traceback (most recent call last):
  File "/usr/local/lib/python3.10/site-packages/aiohttp/connector.py", line 1154, in _create_direct_connection
    hosts = await asyncio.shield(host_resolved)
  File "/usr/local/lib/python3.10/site-packages/aiohttp/connector.py", line 880, in _resolve_host
    addrs = await self._resolver.resolve(host, port, family=self._family)
  File "/usr/local/lib/python3.10/site-packages/aiohttp/resolver.py", line 33, in resolve
    infos = await self._loop.getaddrinfo(
  File "uvloop/loop.pyx", line 1528, in getaddrinfo
socket.gaierror: [Errno -3] Временный сбой в разрешении имен

The above exception was the direct cause of the following exception:

Traceback (most recent call last):
  File "/usr/local/lib/python3.10/site-packages/aiogram/bot/api.py", line 139, in make_request
    async with session.post(url, data=req, **kwargs) as response:
  File "/usr/local/lib/python3.10/site-packages/aiohttp/client.py", line 1138, in __aenter__
    self._resp = await self._coro
  File "/usr/local/lib/python3.10/site-packages/aiohttp/client.py", line 535, in _request
    conn = await self._connector.connect(
  File "/usr/local/lib/python3.10/site-packages/aiohttp/connector.py", line 542, in connect
    proto = await self._create_connection(req, traces, timeout)
  File "/usr/local/lib/python3.10/site-packages/aiohttp/connector.py", line 907, in _create_connection
    _, proto = await self._create_direct_connection(req, traces, timeout)
  File "/usr/local/lib/python3.10/site-packages/aiohttp/connector.py", line 1166, in _create_direct_connection
    raise ClientConnectorError(req.connection_key, exc) from exc
aiohttp.client_exceptions.ClientConnectorError: Cannot connect to host api.telegram.org:443 ssl:default [Временный сбой в разрешении имен]

During handling of the above exception, another exception occurred:

Traceback (most recent call last):
  File "/usr/local/lib/python3.10/site-packages/aiogram/dispatcher/dispatcher.py", line 381, in start_polling
    updates = await self.bot.get_updates(
  File "/usr/local/lib/python3.10/site-packages/aiogram/bot/bot.py", line 110, in get_updates
    result = await self.request(api.Methods.GET_UPDATES, payload)
  File "/usr/local/lib/python3.10/site-packages/aiogram/bot/base.py", line 231, in request
    return await api.make_request(await self.get_session(), self.server, self.__token, method, data, files,
  File "/usr/local/lib/python3.10/site-packages/aiogram/bot/api.py", line 142, in make_request
    raise exceptions.NetworkError(f"aiohttp client throws an error: {e.__class__.__name__}: {e}")
aiogram.utils.exceptions.NetworkError: Aiohttp client throws an error: ClientConnectorError: Cannot connect to host api.telegram.org:443 ssl:default [Временный сбой в разрешении имен]
ERROR:aiogram.dispatcher.dispatcher:Cause exception while getting updates.
Traceback (most recent call last):
  File "/usr/local/lib/python3.10/site-packages/aiohttp/connector.py", line 1154, in _create_direct_connection
    hosts = await asyncio.shield(host_resolved)
  File "/usr/local/lib/python3.10/site-packages/aiohttp/connector.py", line 880, in _resolve_host
    addrs = await self._resolver.resolve(host, port, family=self._family)
  File "/usr/local/lib/python3.10/site-packages/aiohttp/resolver.py", line 33, in resolve
    infos = await self._loop.getaddrinfo(
  File "uvloop/loop.pyx", line 1528, in getaddrinfo
socket.gaierror: [Errno -3] Временный сбой в разрешении имен

The above exception was the direct cause of the following exception:

Traceback (most recent call last):
  File "/usr/local/lib/python3.10/site-packages/aiogram/bot/api.py", line 139, in make_request
    async with session.post(url, data=req, **kwargs) as response:
  File "/usr/local/lib/python3.10/site-packages/aiohttp/client.py", line 1138, in __aenter__
    self._resp = await self._coro
  File "/usr/local/lib/python3.10/site-packages/aiohttp/client.py", line 535, in _request
    conn = await self._connector.connect(
  File "/usr/local/lib/python3.10/site-packages/aiohttp/connector.py", line 542, in connect
    proto = await self._create_connection(req, traces, timeout)
  File "/usr/local/lib/python3.10/site-packages/aiohttp/connector.py", line 907, in _create_connection
    _, proto = await self._create_direct_connection(req, traces, timeout)
  File "/usr/local/lib/python3.10/site-packages/aiohttp/connector.py", line 1166, in _create_direct_connection
    raise ClientConnectorError(req.connection_key, exc) from exc
aiohttp.client_exceptions.ClientConnectorError: Cannot connect to host api.telegram.org:443 ssl:default [Временный сбой в разрешении имен]

During handling of the above exception, another exception occurred:

Traceback (most recent call last):
  File "/usr/local/lib/python3.10/site-packages/aiogram/dispatcher/dispatcher.py", line 381, in start_polling
    updates = await self.bot.get_updates(
  File "/usr/local/lib/python3.10/site-packages/aiogram/bot/bot.py", line 110, in get_updates
    result = await self.request(api.Methods.GET_UPDATES, payload)
  File "/usr/local/lib/python3.10/site-packages/aiogram/bot/base.py", line 231, in request
    return await api.make_request(await self.get_session(), self.server, self.__token, method, data, files,
  File "/usr/local/lib/python3.10/site-packages/aiogram/bot/api.py", line 142, in make_request
    raise exceptions.NetworkError(f"aiohttp client throws an error: {e.__class__.__name__}: {e}")
aiogram.utils.exceptions.NetworkError: Aiohttp client throws an error: ClientConnectorError: Cannot connect to host api.telegram.org:443 ssl:default [Временный сбой в разрешении имен]
ERROR:aiogram.dispatcher.dispatcher:Cause exception while getting updates.
Traceback (most recent call last):
  File "/usr/local/lib/python3.10/site-packages/aiohttp/connector.py", line 1154, in _create_direct_connection
    hosts = await asyncio.shield(host_resolved)
  File "/usr/local/lib/python3.10/site-packages/aiohttp/connector.py", line 880, in _resolve_host
    addrs = await self._resolver.resolve(host, port, family=self._family)
  File "/usr/local/lib/python3.10/site-packages/aiohttp/resolver.py", line 33, in resolve
    infos = await self._loop.getaddrinfo(
  File "uvloop/loop.pyx", line 1528, in getaddrinfo
socket.gaierror: [Errno -3] Временный сбой в разрешении имен

The above exception was the direct cause of the following exception:

Traceback (most recent call last):
  File "/usr/local/lib/python3.10/site-packages/aiogram/bot/api.py", line 139, in make_request
    async with session.post(url, data=req, **kwargs) as response:
  File "/usr/local/lib/python3.10/site-packages/aiohttp/client.py", line 1138, in __aenter__
    self._resp = await self._coro
  File "/usr/local/lib/python3.10/site-packages/aiohttp/client.py", line 535, in _request
    conn = await self._connector.connect(
  File "/usr/local/lib/python3.10/site-packages/aiohttp/connector.py", line 542, in connect
    proto = await self._create_connection(req, traces, timeout)
  File "/usr/local/lib/python3.10/site-packages/aiohttp/connector.py", line 907, in _create_connection
    _, proto = await self._create_direct_connection(req, traces, timeout)
  File "/usr/local/lib/python3.10/site-packages/aiohttp/connector.py", line 1166, in _create_direct_connection
    raise ClientConnectorError(req.connection_key, exc) from exc
aiohttp.client_exceptions.ClientConnectorError: Cannot connect to host api.telegram.org:443 ssl:default [Временный сбой в разрешении имен]

During handling of the above exception, another exception occurred:

Traceback (most recent call last):
  File "/usr/local/lib/python3.10/site-packages/aiogram/dispatcher/dispatcher.py", line 381, in start_polling
    updates = await self.bot.get_updates(
  File "/usr/local/lib/python3.10/site-packages/aiogram/bot/bot.py", line 110, in get_updates
    result = await self.request(api.Methods.GET_UPDATES, payload)
  File "/usr/local/lib/python3.10/site-packages/aiogram/bot/base.py", line 231, in request
    return await api.make_request(await self.get_session(), self.server, self.__token, method, data, files,
  File "/usr/local/lib/python3.10/site-packages/aiogram/bot/api.py", line 142, in make_request
    raise exceptions.NetworkError(f"aiohttp client throws an error: {e.__class__.__name__}: {e}")
aiogram.utils.exceptions.NetworkError: Aiohttp client throws an error: ClientConnectorError: Cannot connect to host api.telegram.org:443 ssl:default [Временный сбой в разрешении имен]
ERROR:aiogram.dispatcher.dispatcher:Cause exception while getting updates.
Traceback (most recent call last):
  File "/usr/local/lib/python3.10/site-packages/aiohttp/connector.py", line 1154, in _create_direct_connection
    hosts = await asyncio.shield(host_resolved)
  File "/usr/local/lib/python3.10/site-packages/aiohttp/connector.py", line 880, in _resolve_host
    addrs = await self._resolver.resolve(host, port, family=self._family)
  File "/usr/local/lib/python3.10/site-packages/aiohttp/resolver.py", line 33, in resolve
    infos = await self._loop.getaddrinfo(
  File "uvloop/loop.pyx", line 1528, in getaddrinfo
socket.gaierror: [Errno -3] Временный сбой в разрешении имен

The above exception was the direct cause of the following exception:

Traceback (most recent call last):
  File "/usr/local/lib/python3.10/site-packages/aiogram/bot/api.py", line 139, in make_request
    async with session.post(url, data=req, **kwargs) as response:
  File "/usr/local/lib/python3.10/site-packages/aiohttp/client.py", line 1138, in __aenter__
    self._resp = await self._coro
  File "/usr/local/lib/python3.10/site-packages/aiohttp/client.py", line 535, in _request
    conn = await self._connector.connect(
  File "/usr/local/lib/python3.10/site-packages/aiohttp/connector.py", line 542, in connect
    proto = await self._create_connection(req, traces, timeout)
  File "/usr/local/lib/python3.10/site-packages/aiohttp/connector.py", line 907, in _create_connection
    _, proto = await self._create_direct_connection(req, traces, timeout)
  File "/usr/local/lib/python3.10/site-packages/aiohttp/connector.py", line 1166, in _create_direct_connection
    raise ClientConnectorError(req.connection_key, exc) from exc
aiohttp.client_exceptions.ClientConnectorError: Cannot connect to host api.telegram.org:443 ssl:default [Временный сбой в разрешении имен]

During handling of the above exception, another exception occurred:

Traceback (most recent call last):
  File "/usr/local/lib/python3.10/site-packages/aiogram/dispatcher/dispatcher.py", line 381, in start_polling
    updates = await self.bot.get_updates(
  File "/usr/local/lib/python3.10/site-packages/aiogram/bot/bot.py", line 110, in get_updates
    result = await self.request(api.Methods.GET_UPDATES, payload)
  File "/usr/local/lib/python3.10/site-packages/aiogram/bot/base.py", line 231, in request
    return await api.make_request(await self.get_session(), self.server, self.__token, method, data, files,
  File "/usr/local/lib/python3.10/site-packages/aiogram/bot/api.py", line 142, in make_request
    raise exceptions.NetworkError(f"aiohttp client throws an error: {e.__class__.__name__}: {e}")
aiogram.utils.exceptions.NetworkError: Aiohttp client throws an error: ClientConnectorError: Cannot connect to host api.telegram.org:443 ssl:default [Временный сбой в разрешении имен]
ERROR:aiogram.dispatcher.dispatcher:Cause exception while getting updates.
Traceback (most recent call last):
  File "/usr/local/lib/python3.10/site-packages/aiohttp/connector.py", line 1154, in _create_direct_connection
    hosts = await asyncio.shield(host_resolved)
  File "/usr/local/lib/python3.10/site-packages/aiohttp/connector.py", line 880, in _resolve_host
    addrs = await self._resolver.resolve(host, port, family=self._family)
  File "/usr/local/lib/python3.10/site-packages/aiohttp/resolver.py", line 33, in resolve
    infos = await self._loop.getaddrinfo(
  File "uvloop/loop.pyx", line 1528, in getaddrinfo
socket.gaierror: [Errno -3] Временный сбой в разрешении имен

The above exception was the direct cause of the following exception:

Traceback (most recent call last):
  File "/usr/local/lib/python3.10/site-packages/aiogram/bot/api.py", line 139, in make_request
    async with session.post(url, data=req, **kwargs) as response:
  File "/usr/local/lib/python3.10/site-packages/aiohttp/client.py", line 1138, in __aenter__
    self._resp = await self._coro
  File "/usr/local/lib/python3.10/site-packages/aiohttp/client.py", line 535, in _request
    conn = await self._connector.connect(
  File "/usr/local/lib/python3.10/site-packages/aiohttp/connector.py", line 542, in connect
    proto = await self._create_connection(req, traces, timeout)
  File "/usr/local/lib/python3.10/site-packages/aiohttp/connector.py", line 907, in _create_connection
    _, proto = await self._create_direct_connection(req, traces, timeout)
  File "/usr/local/lib/python3.10/site-packages/aiohttp/connector.py", line 1166, in _create_direct_connection
    raise ClientConnectorError(req.connection_key, exc) from exc
aiohttp.client_exceptions.ClientConnectorError: Cannot connect to host api.telegram.org:443 ssl:default [Временный сбой в разрешении имен]

During handling of the above exception, another exception occurred:

Traceback (most recent call last):
  File "/usr/local/lib/python3.10/site-packages/aiogram/dispatcher/dispatcher.py", line 381, in start_polling
    updates = await self.bot.get_updates(
  File "/usr/local/lib/python3.10/site-packages/aiogram/bot/bot.py", line 110, in get_updates
    result = await self.request(api.Methods.GET_UPDATES, payload)
  File "/usr/local/lib/python3.10/site-packages/aiogram/bot/base.py", line 231, in request
    return await api.make_request(await self.get_session(), self.server, self.__token, method, data, files,
  File "/usr/local/lib/python3.10/site-packages/aiogram/bot/api.py", line 142, in make_request
    raise exceptions.NetworkError(f"aiohttp client throws an error: {e.__class__.__name__}: {e}")
aiogram.utils.exceptions.NetworkError: Aiohttp client throws an error: ClientConnectorError: Cannot connect to host api.telegram.org:443 ssl:default [Временный сбой в разрешении имен]
ERROR:aiogram.dispatcher.dispatcher:Cause exception while getting updates.
Traceback (most recent call last):
  File "/usr/local/lib/python3.10/site-packages/aiohttp/connector.py", line 1154, in _create_direct_connection
    hosts = await asyncio.shield(host_resolved)
  File "/usr/local/lib/python3.10/site-packages/aiohttp/connector.py", line 880, in _resolve_host
    addrs = await self._resolver.resolve(host, port, family=self._family)
  File "/usr/local/lib/python3.10/site-packages/aiohttp/resolver.py", line 33, in resolve
    infos = await self._loop.getaddrinfo(
  File "uvloop/loop.pyx", line 1528, in getaddrinfo
socket.gaierror: [Errno -3] Временный сбой в разрешении имен

The above exception was the direct cause of the following exception:

Traceback (most recent call last):
  File "/usr/local/lib/python3.10/site-packages/aiogram/bot/api.py", line 139, in make_request
    async with session.post(url, data=req, **kwargs) as response:
  File "/usr/local/lib/python3.10/site-packages/aiohttp/client.py", line 1138, in __aenter__
    self._resp = await self._coro
  File "/usr/local/lib/python3.10/site-packages/aiohttp/client.py", line 535, in _request
    conn = await self._connector.connect(
  File "/usr/local/lib/python3.10/site-packages/aiohttp/connector.py", line 542, in connect
    proto = await self._create_connection(req, traces, timeout)
  File "/usr/local/lib/python3.10/site-packages/aiohttp/connector.py", line 907, in _create_connection
    _, proto = await self._create_direct_connection(req, traces, timeout)
  File "/usr/local/lib/python3.10/site-packages/aiohttp/connector.py", line 1166, in _create_direct_connection
    raise ClientConnectorError(req.connection_key, exc) from exc
aiohttp.client_exceptions.ClientConnectorError: Cannot connect to host api.telegram.org:443 ssl:default [Временный сбой в разрешении имен]

During handling of the above exception, another exception occurred:

Traceback (most recent call last):
  File "/usr/local/lib/python3.10/site-packages/aiogram/dispatcher/dispatcher.py", line 381, in start_polling
    updates = await self.bot.get_updates(
  File "/usr/local/lib/python3.10/site-packages/aiogram/bot/bot.py", line 110, in get_updates
    result = await self.request(api.Methods.GET_UPDATES, payload)
  File "/usr/local/lib/python3.10/site-packages/aiogram/bot/base.py", line 231, in request
    return await api.make_request(await self.get_session(), self.server, self.__token, method, data, files,
  File "/usr/local/lib/python3.10/site-packages/aiogram/bot/api.py", line 142, in make_request
    raise exceptions.NetworkError(f"aiohttp client throws an error: {e.__class__.__name__}: {e}")
aiogram.utils.exceptions.NetworkError: Aiohttp client throws an error: ClientConnectorError: Cannot connect to host api.telegram.org:443 ssl:default [Временный сбой в разрешении имен]
ERROR:aiogram.dispatcher.dispatcher:Cause exception while getting updates.
Traceback (most recent call last):
  File "/usr/local/lib/python3.10/site-packages/aiohttp/connector.py", line 1154, in _create_direct_connection
    hosts = await asyncio.shield(host_resolved)
  File "/usr/local/lib/python3.10/site-packages/aiohttp/connector.py", line 880, in _resolve_host
    addrs = await self._resolver.resolve(host, port, family=self._family)
  File "/usr/local/lib/python3.10/site-packages/aiohttp/resolver.py", line 33, in resolve
    infos = await self._loop.getaddrinfo(
  File "uvloop/loop.pyx", line 1528, in getaddrinfo
socket.gaierror: [Errno -3] Временный сбой в разрешении имен

The above exception was the direct cause of the following exception:

Traceback (most recent call last):
  File "/usr/local/lib/python3.10/site-packages/aiogram/bot/api.py", line 139, in make_request
    async with session.post(url, data=req, **kwargs) as response:
  File "/usr/local/lib/python3.10/site-packages/aiohttp/client.py", line 1138, in __aenter__
    self._resp = await self._coro
  File "/usr/local/lib/python3.10/site-packages/aiohttp/client.py", line 535, in _request
    conn = await self._connector.connect(
  File "/usr/local/lib/python3.10/site-packages/aiohttp/connector.py", line 542, in connect
    proto = await self._create_connection(req, traces, timeout)
  File "/usr/local/lib/python3.10/site-packages/aiohttp/connector.py", line 907, in _create_connection
    _, proto = await self._create_direct_connection(req, traces, timeout)
  File "/usr/local/lib/python3.10/site-packages/aiohttp/connector.py", line 1166, in _create_direct_connection
    raise ClientConnectorError(req.connection_key, exc) from exc
aiohttp.client_exceptions.ClientConnectorError: Cannot connect to host api.telegram.org:443 ssl:default [Временный сбой в разрешении имен]

During handling of the above exception, another exception occurred:

Traceback (most recent call last):
  File "/usr/local/lib/python3.10/site-packages/aiogram/dispatcher/dispatcher.py", line 381, in start_polling
    updates = await self.bot.get_updates(
  File "/usr/local/lib/python3.10/site-packages/aiogram/bot/bot.py", line 110, in get_updates
    result = await self.request(api.Methods.GET_UPDATES, payload)
  File "/usr/local/lib/python3.10/site-packages/aiogram/bot/base.py", line 231, in request
    return await api.make_request(await self.get_session(), self.server, self.__token, method, data, files,
  File "/usr/local/lib/python3.10/site-packages/aiogram/bot/api.py", line 142, in make_request
    raise exceptions.NetworkError(f"aiohttp client throws an error: {e.__class__.__name__}: {e}")
aiogram.utils.exceptions.NetworkError: Aiohttp client throws an error: ClientConnectorError: Cannot connect to host api.telegram.org:443 ssl:default [Временный сбой в разрешении имен]
ERROR:aiogram.dispatcher.dispatcher:Cause exception while getting updates.
Traceback (most recent call last):
  File "/usr/local/lib/python3.10/site-packages/aiohttp/connector.py", line 1154, in _create_direct_connection
    hosts = await asyncio.shield(host_resolved)
  File "/usr/local/lib/python3.10/site-packages/aiohttp/connector.py", line 880, in _resolve_host
    addrs = await self._resolver.resolve(host, port, family=self._family)
  File "/usr/local/lib/python3.10/site-packages/aiohttp/resolver.py", line 33, in resolve
    infos = await self._loop.getaddrinfo(
  File "uvloop/loop.pyx", line 1528, in getaddrinfo
socket.gaierror: [Errno -3] Временный сбой в разрешении имен

The above exception was the direct cause of the following exception:

Traceback (most recent call last):
  File "/usr/local/lib/python3.10/site-packages/aiogram/bot/api.py", line 139, in make_request
    async with session.post(url, data=req, **kwargs) as response:
  File "/usr/local/lib/python3.10/site-packages/aiohttp/client.py", line 1138, in __aenter__
    self._resp = await self._coro
  File "/usr/local/lib/python3.10/site-packages/aiohttp/client.py", line 535, in _request
    conn = await self._connector.connect(
  File "/usr/local/lib/python3.10/site-packages/aiohttp/connector.py", line 542, in connect
    proto = await self._create_connection(req, traces, timeout)
  File "/usr/local/lib/python3.10/site-packages/aiohttp/connector.py", line 907, in _create_connection
    _, proto = await self._create_direct_connection(req, traces, timeout)
  File "/usr/local/lib/python3.10/site-packages/aiohttp/connector.py", line 1166, in _create_direct_connection
    raise ClientConnectorError(req.connection_key, exc) from exc
aiohttp.client_exceptions.ClientConnectorError: Cannot connect to host api.telegram.org:443 ssl:default [Временный сбой в разрешении имен]

During handling of the above exception, another exception occurred:

Traceback (most recent call last):
  File "/usr/local/lib/python3.10/site-packages/aiogram/dispatcher/dispatcher.py", line 381, in start_polling
    updates = await self.bot.get_updates(
  File "/usr/local/lib/python3.10/site-packages/aiogram/bot/bot.py", line 110, in get_updates
    result = await self.request(api.Methods.GET_UPDATES, payload)
  File "/usr/local/lib/python3.10/site-packages/aiogram/bot/base.py", line 231, in request
    return await api.make_request(await self.get_session(), self.server, self.__token, method, data, files,
  File "/usr/local/lib/python3.10/site-packages/aiogram/bot/api.py", line 142, in make_request
    raise exceptions.NetworkError(f"aiohttp client throws an error: {e.__class__.__name__}: {e}")
aiogram.utils.exceptions.NetworkError: Aiohttp client throws an error: ClientConnectorError: Cannot connect to host api.telegram.org:443 ssl:default [Временный сбой в разрешении имен]
ERROR:aiogram.dispatcher.dispatcher:Cause exception while getting updates.
Traceback (most recent call last):
  File "/usr/local/lib/python3.10/site-packages/aiohttp/connector.py", line 1154, in _create_direct_connection
    hosts = await asyncio.shield(host_resolved)
  File "/usr/local/lib/python3.10/site-packages/aiohttp/connector.py", line 880, in _resolve_host
    addrs = await self._resolver.resolve(host, port, family=self._family)
  File "/usr/local/lib/python3.10/site-packages/aiohttp/resolver.py", line 33, in resolve
    infos = await self._loop.getaddrinfo(
  File "uvloop/loop.pyx", line 1528, in getaddrinfo
socket.gaierror: [Errno -3] Временный сбой в разрешении имен

The above exception was the direct cause of the following exception:

Traceback (most recent call last):
  File "/usr/local/lib/python3.10/site-packages/aiogram/bot/api.py", line 139, in make_request
    async with session.post(url, data=req, **kwargs) as response:
  File "/usr/local/lib/python3.10/site-packages/aiohttp/client.py", line 1138, in __aenter__
    self._resp = await self._coro
  File "/usr/local/lib/python3.10/site-packages/aiohttp/client.py", line 535, in _request
    conn = await self._connector.connect(
  File "/usr/local/lib/python3.10/site-packages/aiohttp/connector.py", line 542, in connect
    proto = await self._create_connection(req, traces, timeout)
  File "/usr/local/lib/python3.10/site-packages/aiohttp/connector.py", line 907, in _create_connection
    _, proto = await self._create_direct_connection(req, traces, timeout)
  File "/usr/local/lib/python3.10/site-packages/aiohttp/connector.py", line 1166, in _create_direct_connection
    raise ClientConnectorError(req.connection_key, exc) from exc
aiohttp.client_exceptions.ClientConnectorError: Cannot connect to host api.telegram.org:443 ssl:default [Временный сбой в разрешении имен]

During handling of the above exception, another exception occurred:

Traceback (most recent call last):
  File "/usr/local/lib/python3.10/site-packages/aiogram/dispatcher/dispatcher.py", line 381, in start_polling
    updates = await self.bot.get_updates(
  File "/usr/local/lib/python3.10/site-packages/aiogram/bot/bot.py", line 110, in get_updates
    result = await self.request(api.Methods.GET_UPDATES, payload)
  File "/usr/local/lib/python3.10/site-packages/aiogram/bot/base.py", line 231, in request
    return await api.make_request(await self.get_session(), self.server, self.__token, method, data, files,
  File "/usr/local/lib/python3.10/site-packages/aiogram/bot/api.py", line 142, in make_request
    raise exceptions.NetworkError(f"aiohttp client throws an error: {e.__class__.__name__}: {e}")
aiogram.utils.exceptions.NetworkError: Aiohttp client throws an error: ClientConnectorError: Cannot connect to host api.telegram.org:443 ssl:default [Временный сбой в разрешении имен]
ERROR:aiogram.dispatcher.dispatcher:Cause exception while getting updates.
Traceback (most recent call last):
  File "/usr/local/lib/python3.10/site-packages/aiogram/bot/api.py", line 139, in make_request
    async with session.post(url, data=req, **kwargs) as response:
  File "/usr/local/lib/python3.10/site-packages/aiohttp/client.py", line 1138, in __aenter__
    self._resp = await self._coro
  File "/usr/local/lib/python3.10/site-packages/aiohttp/client.py", line 559, in _request
    await resp.start(conn)
  File "/usr/local/lib/python3.10/site-packages/aiohttp/client_reqrep.py", line 898, in start
    message, payload = await protocol.read()  # type: ignore[union-attr]
  File "/usr/local/lib/python3.10/site-packages/aiohttp/streams.py", line 616, in read
    await self._waiter
aiohttp.client_exceptions.ClientOSError: [Errno 104] Соединение разорвано другой стороной

During handling of the above exception, another exception occurred:

Traceback (most recent call last):
  File "/usr/local/lib/python3.10/site-packages/aiogram/dispatcher/dispatcher.py", line 381, in start_polling
    updates = await self.bot.get_updates(
  File "/usr/local/lib/python3.10/site-packages/aiogram/bot/bot.py", line 110, in get_updates
    result = await self.request(api.Methods.GET_UPDATES, payload)
  File "/usr/local/lib/python3.10/site-packages/aiogram/bot/base.py", line 231, in request
    return await api.make_request(await self.get_session(), self.server, self.__token, method, data, files,
  File "/usr/local/lib/python3.10/site-packages/aiogram/bot/api.py", line 142, in make_request
    raise exceptions.NetworkError(f"aiohttp client throws an error: {e.__class__.__name__}: {e}")
aiogram.utils.exceptions.NetworkError: Aiohttp client throws an error: ClientOSError: [Errno 104] Соединение разорвано другой стороной
ERROR:aiogram.dispatcher.dispatcher:Cause exception while getting updates.
Traceback (most recent call last):
  File "/usr/local/lib/python3.10/site-packages/aiogram/dispatcher/dispatcher.py", line 381, in start_polling
    updates = await self.bot.get_updates(
  File "/usr/local/lib/python3.10/site-packages/aiogram/bot/bot.py", line 110, in get_updates
    result = await self.request(api.Methods.GET_UPDATES, payload)
  File "/usr/local/lib/python3.10/site-packages/aiogram/bot/base.py", line 231, in request
    return await api.make_request(await self.get_session(), self.server, self.__token, method, data, files,
  File "/usr/local/lib/python3.10/site-packages/aiogram/bot/api.py", line 140, in make_request
    return check_result(method, response.content_type, response.status, await response.text())
  File "/usr/local/lib/python3.10/site-packages/aiogram/bot/api.py", line 128, in check_result
    raise exceptions.TelegramAPIError(description)
aiogram.utils.exceptions.TelegramAPIError: Bad Gateway
ERROR:aiogram.dispatcher.dispatcher:Cause exception while getting updates.
Traceback (most recent call last):
  File "/usr/local/lib/python3.10/site-packages/aiogram/dispatcher/dispatcher.py", line 381, in start_polling
    updates = await self.bot.get_updates(
  File "/usr/local/lib/python3.10/site-packages/aiogram/bot/bot.py", line 110, in get_updates
    result = await self.request(api.Methods.GET_UPDATES, payload)
  File "/usr/local/lib/python3.10/site-packages/aiogram/bot/base.py", line 231, in request
    return await api.make_request(await self.get_session(), self.server, self.__token, method, data, files,
  File "/usr/local/lib/python3.10/site-packages/aiogram/bot/api.py", line 140, in make_request
    return check_result(method, response.content_type, response.status, await response.text())
  File "/usr/local/lib/python3.10/site-packages/aiogram/bot/api.py", line 111, in check_result
    raise exceptions.RetryAfter(parameters.retry_after)
aiogram.utils.exceptions.RetryAfter: Flood control exceeded. Retry in 5 seconds.
ERROR:aiogram.dispatcher.dispatcher:Cause exception while getting updates.
Traceback (most recent call last):
  File "/usr/local/lib/python3.10/site-packages/aiogram/dispatcher/dispatcher.py", line 381, in start_polling
    updates = await self.bot.get_updates(
  File "/usr/local/lib/python3.10/site-packages/aiogram/bot/bot.py", line 110, in get_updates
    result = await self.request(api.Methods.GET_UPDATES, payload)
  File "/usr/local/lib/python3.10/site-packages/aiogram/bot/base.py", line 231, in request
    return await api.make_request(await self.get_session(), self.server, self.__token, method, data, files,
  File "/usr/local/lib/python3.10/site-packages/aiogram/bot/api.py", line 140, in make_request
    return check_result(method, response.content_type, response.status, await response.text())
  File "/usr/local/lib/python3.10/site-packages/aiogram/bot/api.py", line 128, in check_result
    raise exceptions.TelegramAPIError(description)
aiogram.utils.exceptions.TelegramAPIError: Bad Gateway
ERROR:aiogram.dispatcher.dispatcher:Cause exception while getting updates.
Traceback (most recent call last):
  File "/usr/local/lib/python3.10/site-packages/aiogram/dispatcher/dispatcher.py", line 381, in start_polling
    updates = await self.bot.get_updates(
  File "/usr/local/lib/python3.10/site-packages/aiogram/bot/bot.py", line 110, in get_updates
    result = await self.request(api.Methods.GET_UPDATES, payload)
  File "/usr/local/lib/python3.10/site-packages/aiogram/bot/base.py", line 231, in request
    return await api.make_request(await self.get_session(), self.server, self.__token, method, data, files,
  File "/usr/local/lib/python3.10/site-packages/aiogram/bot/api.py", line 140, in make_request
    return check_result(method, response.content_type, response.status, await response.text())
  File "/usr/local/lib/python3.10/site-packages/aiogram/bot/api.py", line 128, in check_result
    raise exceptions.TelegramAPIError(description)
aiogram.utils.exceptions.TelegramAPIError: Bad Gateway
ERROR:aiogram.dispatcher.dispatcher:Cause exception while getting updates.
Traceback (most recent call last):
  File "/usr/local/lib/python3.10/site-packages/aiogram/dispatcher/dispatcher.py", line 381, in start_polling
    updates = await self.bot.get_updates(
  File "/usr/local/lib/python3.10/site-packages/aiogram/bot/bot.py", line 110, in get_updates
    result = await self.request(api.Methods.GET_UPDATES, payload)
  File "/usr/local/lib/python3.10/site-packages/aiogram/bot/base.py", line 231, in request
    return await api.make_request(await self.get_session(), self.server, self.__token, method, data, files,
  File "/usr/local/lib/python3.10/site-packages/aiogram/bot/api.py", line 140, in make_request
    return check_result(method, response.content_type, response.status, await response.text())
  File "/usr/local/lib/python3.10/site-packages/aiogram/bot/api.py", line 128, in check_result
    raise exceptions.TelegramAPIError(description)
aiogram.utils.exceptions.TelegramAPIError: Bad Gateway
ERROR:aiogram.dispatcher.dispatcher:Cause exception while getting updates.
Traceback (most recent call last):
  File "/usr/local/lib/python3.10/site-packages/aiogram/dispatcher/dispatcher.py", line 381, in start_polling
    updates = await self.bot.get_updates(
  File "/usr/local/lib/python3.10/site-packages/aiogram/bot/bot.py", line 110, in get_updates
    result = await self.request(api.Methods.GET_UPDATES, payload)
  File "/usr/local/lib/python3.10/site-packages/aiogram/bot/base.py", line 231, in request
    return await api.make_request(await self.get_session(), self.server, self.__token, method, data, files,
  File "/usr/local/lib/python3.10/site-packages/aiogram/bot/api.py", line 140, in make_request
    return check_result(method, response.content_type, response.status, await response.text())
  File "/usr/local/lib/python3.10/site-packages/aiogram/bot/api.py", line 128, in check_result
    raise exceptions.TelegramAPIError(description)
aiogram.utils.exceptions.TelegramAPIError: Bad Gateway
ERROR:aiogram.dispatcher.dispatcher:Cause exception while getting updates.
Traceback (most recent call last):
  File "/usr/local/lib/python3.10/site-packages/aiogram/bot/api.py", line 139, in make_request
    async with session.post(url, data=req, **kwargs) as response:
  File "/usr/local/lib/python3.10/site-packages/aiohttp/client.py", line 1138, in __aenter__
    self._resp = await self._coro
  File "/usr/local/lib/python3.10/site-packages/aiohttp/client.py", line 559, in _request
    await resp.start(conn)
  File "/usr/local/lib/python3.10/site-packages/aiohttp/client_reqrep.py", line 898, in start
    message, payload = await protocol.read()  # type: ignore[union-attr]
  File "/usr/local/lib/python3.10/site-packages/aiohttp/streams.py", line 616, in read
    await self._waiter
aiohttp.client_exceptions.ClientOSError: [Errno 104] Соединение разорвано другой стороной

During handling of the above exception, another exception occurred:

Traceback (most recent call last):
  File "/usr/local/lib/python3.10/site-packages/aiogram/dispatcher/dispatcher.py", line 381, in start_polling
    updates = await self.bot.get_updates(
  File "/usr/local/lib/python3.10/site-packages/aiogram/bot/bot.py", line 110, in get_updates
    result = await self.request(api.Methods.GET_UPDATES, payload)
  File "/usr/local/lib/python3.10/site-packages/aiogram/bot/base.py", line 231, in request
    return await api.make_request(await self.get_session(), self.server, self.__token, method, data, files,
  File "/usr/local/lib/python3.10/site-packages/aiogram/bot/api.py", line 142, in make_request
    raise exceptions.NetworkError(f"aiohttp client throws an error: {e.__class__.__name__}: {e}")
aiogram.utils.exceptions.NetworkError: Aiohttp client throws an error: ClientOSError: [Errno 104] Соединение разорвано другой стороной
ERROR:aiogram.dispatcher.dispatcher:Cause exception while getting updates.
Traceback (most recent call last):
  File "/usr/local/lib/python3.10/site-packages/aiogram/bot/api.py", line 139, in make_request
    async with session.post(url, data=req, **kwargs) as response:
  File "/usr/local/lib/python3.10/site-packages/aiohttp/client.py", line 1138, in __aenter__
    self._resp = await self._coro
  File "/usr/local/lib/python3.10/site-packages/aiohttp/client.py", line 559, in _request
    await resp.start(conn)
  File "/usr/local/lib/python3.10/site-packages/aiohttp/client_reqrep.py", line 898, in start
    message, payload = await protocol.read()  # type: ignore[union-attr]
  File "/usr/local/lib/python3.10/site-packages/aiohttp/streams.py", line 616, in read
    await self._waiter
aiohttp.client_exceptions.ClientOSError: [Errno 104] Соединение разорвано другой стороной

During handling of the above exception, another exception occurred:

Traceback (most recent call last):
  File "/usr/local/lib/python3.10/site-packages/aiogram/dispatcher/dispatcher.py", line 381, in start_polling
    updates = await self.bot.get_updates(
  File "/usr/local/lib/python3.10/site-packages/aiogram/bot/bot.py", line 110, in get_updates
    result = await self.request(api.Methods.GET_UPDATES, payload)
  File "/usr/local/lib/python3.10/site-packages/aiogram/bot/base.py", line 231, in request
    return await api.make_request(await self.get_session(), self.server, self.__token, method, data, files,
  File "/usr/local/lib/python3.10/site-packages/aiogram/bot/api.py", line 142, in make_request
    raise exceptions.NetworkError(f"aiohttp client throws an error: {e.__class__.__name__}: {e}")
aiogram.utils.exceptions.NetworkError: Aiohttp client throws an error: ClientOSError: [Errno 104] Соединение разорвано другой стороной
ERROR:aiogram.dispatcher.dispatcher:Cause exception while getting updates.
Traceback (most recent call last):
  File "/usr/local/lib/python3.10/site-packages/aiogram/dispatcher/dispatcher.py", line 381, in start_polling
    updates = await self.bot.get_updates(
  File "/usr/local/lib/python3.10/site-packages/aiogram/bot/bot.py", line 110, in get_updates
    result = await self.request(api.Methods.GET_UPDATES, payload)
  File "/usr/local/lib/python3.10/site-packages/aiogram/bot/base.py", line 231, in request
    return await api.make_request(await self.get_session(), self.server, self.__token, method, data, files,
  File "/usr/local/lib/python3.10/site-packages/aiogram/bot/api.py", line 140, in make_request
    return check_result(method, response.content_type, response.status, await response.text())
  File "/usr/local/lib/python3.10/site-packages/aiogram/bot/api.py", line 128, in check_result
    raise exceptions.TelegramAPIError(description)
aiogram.utils.exceptions.TelegramAPIError: Bad Gateway
ERROR:aiogram.dispatcher.dispatcher:Cause exception while getting updates.
Traceback (most recent call last):
  File "/usr/local/lib/python3.10/site-packages/aiogram/dispatcher/dispatcher.py", line 381, in start_polling
    updates = await self.bot.get_updates(
  File "/usr/local/lib/python3.10/site-packages/aiogram/bot/bot.py", line 110, in get_updates
    result = await self.request(api.Methods.GET_UPDATES, payload)
  File "/usr/local/lib/python3.10/site-packages/aiogram/bot/base.py", line 231, in request
    return await api.make_request(await self.get_session(), self.server, self.__token, method, data, files,
  File "/usr/local/lib/python3.10/site-packages/aiogram/bot/api.py", line 140, in make_request
    return check_result(method, response.content_type, response.status, await response.text())
  File "/usr/local/lib/python3.10/site-packages/aiogram/bot/api.py", line 128, in check_result
    raise exceptions.TelegramAPIError(description)
aiogram.utils.exceptions.TelegramAPIError: Bad Gateway
ERROR:aiogram.dispatcher.dispatcher:Cause exception while getting updates.
Traceback (most recent call last):
  File "/usr/local/lib/python3.10/site-packages/aiogram/dispatcher/dispatcher.py", line 381, in start_polling
    updates = await self.bot.get_updates(
  File "/usr/local/lib/python3.10/site-packages/aiogram/bot/bot.py", line 110, in get_updates
    result = await self.request(api.Methods.GET_UPDATES, payload)
  File "/usr/local/lib/python3.10/site-packages/aiogram/bot/base.py", line 231, in request
    return await api.make_request(await self.get_session(), self.server, self.__token, method, data, files,
  File "/usr/local/lib/python3.10/site-packages/aiogram/bot/api.py", line 140, in make_request
    return check_result(method, response.content_type, response.status, await response.text())
  File "/usr/local/lib/python3.10/site-packages/aiogram/bot/api.py", line 111, in check_result
    raise exceptions.RetryAfter(parameters.retry_after)
aiogram.utils.exceptions.RetryAfter: Flood control exceeded. Retry in 5 seconds.
ERROR:aiogram.dispatcher.dispatcher:Cause exception while getting updates.
Traceback (most recent call last):
  File "/usr/local/lib/python3.10/site-packages/aiogram/dispatcher/dispatcher.py", line 381, in start_polling
    updates = await self.bot.get_updates(
  File "/usr/local/lib/python3.10/site-packages/aiogram/bot/bot.py", line 110, in get_updates
    result = await self.request(api.Methods.GET_UPDATES, payload)
  File "/usr/local/lib/python3.10/site-packages/aiogram/bot/base.py", line 231, in request
    return await api.make_request(await self.get_session(), self.server, self.__token, method, data, files,
  File "/usr/local/lib/python3.10/site-packages/aiogram/bot/api.py", line 140, in make_request
    return check_result(method, response.content_type, response.status, await response.text())
  File "/usr/local/lib/python3.10/site-packages/aiogram/bot/api.py", line 111, in check_result
    raise exceptions.RetryAfter(parameters.retry_after)
aiogram.utils.exceptions.RetryAfter: Flood control exceeded. Retry in 5 seconds.
ERROR:aiogram.dispatcher.dispatcher:Cause exception while getting updates.
Traceback (most recent call last):
  File "/usr/local/lib/python3.10/site-packages/aiogram/dispatcher/dispatcher.py", line 381, in start_polling
    updates = await self.bot.get_updates(
  File "/usr/local/lib/python3.10/site-packages/aiogram/bot/bot.py", line 110, in get_updates
    result = await self.request(api.Methods.GET_UPDATES, payload)
  File "/usr/local/lib/python3.10/site-packages/aiogram/bot/base.py", line 231, in request
    return await api.make_request(await self.get_session(), self.server, self.__token, method, data, files,
  File "/usr/local/lib/python3.10/site-packages/aiogram/bot/api.py", line 140, in make_request
    return check_result(method, response.content_type, response.status, await response.text())
  File "/usr/local/lib/python3.10/site-packages/aiogram/bot/api.py", line 128, in check_result
    raise exceptions.TelegramAPIError(description)
aiogram.utils.exceptions.TelegramAPIError: Bad Gateway
ERROR:aiogram.dispatcher.dispatcher:Cause exception while getting updates.
Traceback (most recent call last):
  File "/usr/local/lib/python3.10/site-packages/aiogram/dispatcher/dispatcher.py", line 381, in start_polling
    updates = await self.bot.get_updates(
  File "/usr/local/lib/python3.10/site-packages/aiogram/bot/bot.py", line 110, in get_updates
    result = await self.request(api.Methods.GET_UPDATES, payload)
  File "/usr/local/lib/python3.10/site-packages/aiogram/bot/base.py", line 231, in request
    return await api.make_request(await self.get_session(), self.server, self.__token, method, data, files,
  File "/usr/local/lib/python3.10/site-packages/aiogram/bot/api.py", line 140, in make_request
    return check_result(method, response.content_type, response.status, await response.text())
  File "/usr/local/lib/python3.10/site-packages/aiogram/bot/api.py", line 111, in check_result
    raise exceptions.RetryAfter(parameters.retry_after)
aiogram.utils.exceptions.RetryAfter: Flood control exceeded. Retry in 5 seconds.
ERROR:aiogram.dispatcher.dispatcher:Cause exception while getting updates.
Traceback (most recent call last):
  File "/usr/local/lib/python3.10/site-packages/aiogram/dispatcher/dispatcher.py", line 381, in start_polling
    updates = await self.bot.get_updates(
  File "/usr/local/lib/python3.10/site-packages/aiogram/bot/bot.py", line 110, in get_updates
    result = await self.request(api.Methods.GET_UPDATES, payload)
  File "/usr/local/lib/python3.10/site-packages/aiogram/bot/base.py", line 231, in request
    return await api.make_request(await self.get_session(), self.server, self.__token, method, data, files,
  File "/usr/local/lib/python3.10/site-packages/aiogram/bot/api.py", line 140, in make_request
    return check_result(method, response.content_type, response.status, await response.text())
  File "/usr/local/lib/python3.10/site-packages/aiogram/bot/api.py", line 128, in check_result
    raise exceptions.TelegramAPIError(description)
aiogram.utils.exceptions.TelegramAPIError: Bad Gateway
ERROR:aiogram.dispatcher.dispatcher:Cause exception while getting updates.
Traceback (most recent call last):
  File "/usr/local/lib/python3.10/site-packages/aiogram/dispatcher/dispatcher.py", line 381, in start_polling
    updates = await self.bot.get_updates(
  File "/usr/local/lib/python3.10/site-packages/aiogram/bot/bot.py", line 110, in get_updates
    result = await self.request(api.Methods.GET_UPDATES, payload)
  File "/usr/local/lib/python3.10/site-packages/aiogram/bot/base.py", line 231, in request
    return await api.make_request(await self.get_session(), self.server, self.__token, method, data, files,
  File "/usr/local/lib/python3.10/site-packages/aiogram/bot/api.py", line 140, in make_request
    return check_result(method, response.content_type, response.status, await response.text())
  File "/usr/local/lib/python3.10/site-packages/aiogram/bot/api.py", line 128, in check_result
    raise exceptions.TelegramAPIError(description)
aiogram.utils.exceptions.TelegramAPIError: Bad Gateway
ERROR:aiogram.dispatcher.dispatcher:Cause exception while getting updates.
Traceback (most recent call last):
  File "/usr/local/lib/python3.10/site-packages/aiogram/dispatcher/dispatcher.py", line 381, in start_polling
    updates = await self.bot.get_updates(
  File "/usr/local/lib/python3.10/site-packages/aiogram/bot/bot.py", line 110, in get_updates
    result = await self.request(api.Methods.GET_UPDATES, payload)
  File "/usr/local/lib/python3.10/site-packages/aiogram/bot/base.py", line 231, in request
    return await api.make_request(await self.get_session(), self.server, self.__token, method, data, files,
  File "/usr/local/lib/python3.10/site-packages/aiogram/bot/api.py", line 140, in make_request
    return check_result(method, response.content_type, response.status, await response.text())
  File "/usr/local/lib/python3.10/site-packages/aiogram/bot/api.py", line 128, in check_result
    raise exceptions.TelegramAPIError(description)
aiogram.utils.exceptions.TelegramAPIError: Bad Gateway
